{"uuid": "c6bb4403-81d4-47f6-b5ee-21cc34300885", "children": ["9c2c3828-7f0d-4370-8128-3d968b490b10", "64f58c38-2dbd-486a-ba22-ea584af26dfa", "1eef3f59-4fec-4ef0-91e2-a01fc19537e9", "f4f87cce-8722-4691-9b56-e6ed799dca50", "8a10d93b-dd8c-40c9-a5ec-9be9fa01fbfd", "94f6e713-16ae-4f94-8792-7b721b568f46", "dca80cdf-ef94-476a-9d64-1c8069286ecc", "98a2a718-85db-47fd-b8fc-5e3d107671ce", "2db5513f-2194-4f01-b8f8-10e675a06afa", "64fefad3-b3cf-4da1-9e60-5531ead3c083", "2e327331-8779-43ef-8f78-148023175849", "7256d8cb-ab4c-4560-af70-ff411bd1612c", "c451856b-dbdc-47fc-bfba-3a7afd782952", "13c6b859-aace-4f46-b04a-5ae4a887f4c3", "b98dc964-3de3-4228-b43a-380442a6d63b", "1149dd5d-ae7d-4d4d-8e12-bb23cd90d5d3", "b8c0036b-083e-4ed8-b1f0-608f83752f5d", "9f3aeb48-9ea7-4255-b18d-0714201a2881", "b5b07cab-1844-4cb4-bfbb-fa27088906b7"], "befores": [{"name": "logged_session", "status": "failed", "statusDetails": {"message": "Failed: uat环境登录失败（已重试5次）: HTTPSConnectionPool(host='dev.lgcopytrade.top', port=443): Max retries exceeded with url: /api/sys/randomImage/1757985384409?_t=1757985384 (Caused by ProxyError('Unable to connect to proxy', FileNotFoundError(2, 'No such file or directory')))\n", "trace": "  File \"D:\\pycharm_test\\venv\\lib\\site-packages\\pluggy\\_callers.py\", line 167, in _multicall\n    teardown.throw(outcome._exception)\n  File \"D:\\pycharm_test\\venv\\lib\\site-packages\\_pytest\\setuponly.py\", line 36, in pytest_fixture_setup\n    return (yield)\n  File \"D:\\pycharm_test\\venv\\lib\\site-packages\\pluggy\\_callers.py\", line 103, in _multicall\n    res = hook_impl.function(*args)\n  File \"D:\\pycharm_test\\venv\\lib\\site-packages\\_pytest\\fixtures.py\", line 1140, in pytest_fixture_setup\n    result = call_fixture_func(fixturefunc, request, kwargs)\n  File \"D:\\pycharm_test\\venv\\lib\\site-packages\\_pytest\\fixtures.py\", line 891, in call_fixture_func\n    fixture_result = next(generator)\n  File \"D:\\pycharm_test\\template\\conftest.py\", line 192, in logged_session\n    pytest.fail(f\"{environment.value}环境登录失败（已重试{max_retries}次）: {str(e)}\", pytrace=False)\n  File \"D:\\pycharm_test\\venv\\lib\\site-packages\\_pytest\\outcomes.py\", line 178, in fail\n    raise Failed(msg=reason, pytrace=pytrace)\n"}, "start": 1757985344306, "stop": 1757985384423}], "start": 1757985344306, "stop": 1757985385589}