{"name": "任务中心-MT4绑定审核-提取数据2", "status": "failed", "statusDetails": {"message": "Failed: uat环境登录失败（已重试5次）: HTTPSConnectionPool(host='dev.lgcopytrade.top', port=443): Max retries exceeded with url: /api/sys/randomImage/1757985384409?_t=1757985384 (Caused by ProxyError('Unable to connect to proxy', FileNotFoundError(2, 'No such file or directory')))", "trace": "[Errno 2] No such file or directory\n\nThe above exception was the direct cause of the following exception:\nTraceback (most recent call last):\n  File \"D:\\pycharm_test\\venv\\lib\\site-packages\\urllib3\\connectionpool.py\", line 775, in urlopen\n    self._prepare_proxy(conn)\n  File \"D:\\pycharm_test\\venv\\lib\\site-packages\\urllib3\\connectionpool.py\", line 1044, in _prepare_proxy\n    conn.connect()\n  File \"D:\\pycharm_test\\venv\\lib\\site-packages\\urllib3\\connection.py\", line 702, in connect\n    self.sock = sock = self._connect_tls_proxy(self.host, sock)\n  File \"D:\\pycharm_test\\venv\\lib\\site-packages\\urllib3\\connection.py\", line 802, in _connect_tls_proxy\n    sock_and_verified = _ssl_wrap_socket_and_match_hostname(\n  File \"D:\\pycharm_test\\venv\\lib\\site-packages\\urllib3\\connection.py\", line 909, in _ssl_wrap_socket_and_match_hostname\n    ssl_sock = ssl_wrap_socket(\n  File \"D:\\pycharm_test\\venv\\lib\\site-packages\\urllib3\\util\\ssl_.py\", line 469, in ssl_wrap_socket\n    ssl_sock = _ssl_wrap_socket_impl(sock, context, tls_in_tls, server_hostname)\n  File \"D:\\pycharm_test\\venv\\lib\\site-packages\\urllib3\\util\\ssl_.py\", line 513, in _ssl_wrap_socket_impl\n    return ssl_context.wrap_socket(sock, server_hostname=server_hostname)\n  File \"D:\\python_tools\\python\\lib\\ssl.py\", line 500, in wrap_socket\n    return self.sslsocket_class._create(\n  File \"D:\\python_tools\\python\\lib\\ssl.py\", line 1040, in _create\n    self.do_handshake()\n  File \"D:\\python_tools\\python\\lib\\ssl.py\", line 1309, in do_handshake\n    self._sslobj.do_handshake()\nFileNotFoundError: [Errno 2] No such file or directory\n\nThe above exception was the direct cause of the following exception:\n\nurllib3.exceptions.ProxyError: ('Unable to connect to proxy', FileNotFoundError(2, 'No such file or directory'))\n\nThe above exception was the direct cause of the following exception:\nHTTPSConnectionPool(host='dev.lgcopytrade.top', port=443): Max retries exceeded with url: /api/sys/randomImage/1757985384409?_t=1757985384 (Caused by ProxyError('Unable to connect to proxy', FileNotFoundError(2, 'No such file or directory')))\n\nDuring handling of the above exception, another exception occurred:\nHTTPSConnectionPool(host='dev.lgcopytrade.top', port=443): Max retries exceeded with url: /api/sys/randomImage/1757985384409?_t=1757985384 (Caused by ProxyError('Unable to connect to proxy', FileNotFoundError(2, 'No such file or directory')))\n\nDuring handling of the above exception, another exception occurred:\nuat环境登录失败（已重试5次）: HTTPSConnectionPool(host='dev.lgcopytrade.top', port=443): Max retries exceeded with url: /api/sys/randomImage/1757985384409?_t=1757985384 (Caused by ProxyError('Unable to connect to proxy', FileNotFoundError(2, 'No such file or directory')))"}, "start": 1757985384491, "stop": 1757985384491, "uuid": "dca80cdf-ef94-476a-9d64-1c8069286ecc", "historyId": "183f2c77153af6fada891c5bf3c281f7", "testCaseId": "183f2c77153af6fada891c5bf3c281f7", "fullName": "test_cloudTrader.test_create.Test_trader#test_api_getData0", "labels": [{"name": "story", "value": "创建交易员账号"}, {"name": "feature", "value": "账号管理"}, {"name": "parentSuite", "value": "test_cloudTrader"}, {"name": "suite", "value": "test_create"}, {"name": "subSuite", "value": "Test_create"}, {"name": "host", "value": "DESKTOP-4S9CU1E"}, {"name": "thread", "value": "26392-MainThread"}, {"name": "framework", "value": "pytest"}, {"name": "language", "value": "cpython3"}, {"name": "package", "value": "test_cloudTrader.test_create"}]}