INFO     self_developed_model.conftest:conftest.py:62 [2025-10-09 14:21:30] 用例 test_vps/test_delete.py::TestDeleteUser::test_deleteTemplate 开始登录，环境: uat
INFO     self_developed_model.conftest:conftest.py:100 UAT登录尝试 1/5，MFA验证码: 26787
DEBUG    urllib3.connectionpool:connectionpool.py:1051 Starting new HTTPS connection (1): uat.atcp.top:443
DEBUG    urllib3.connectionpool:connectionpool.py:546 https://uat.atcp.top:443 "POST /api/sys/auth/login HTTP/11" 200 None
ERROR    self_developed_model.conftest:conftest.py:129 第1次登录失败: 登录失败: MFA验证失败
INFO     self_developed_model.conftest:conftest.py:100 UAT登录尝试 2/5，MFA验证码: 26787
DEBUG    urllib3.connectionpool:connectionpool.py:546 https://uat.atcp.top:443 "POST /api/sys/auth/login HTTP/11" 200 None
ERROR    self_developed_model.conftest:conftest.py:129 第2次登录失败: 登录失败: MFA验证失败
INFO     self_developed_model.conftest:conftest.py:100 UAT登录尝试 3/5，MFA验证码: 26787
DEBUG    urllib3.connectionpool:connectionpool.py:546 https://uat.atcp.top:443 "POST /api/sys/auth/login HTTP/11" 200 None
ERROR    self_developed_model.conftest:conftest.py:129 第3次登录失败: 登录失败: MFA验证失败
INFO     self_developed_model.conftest:conftest.py:100 UAT登录尝试 4/5，MFA验证码: 248708
DEBUG    urllib3.connectionpool:connectionpool.py:546 https://uat.atcp.top:443 "POST /api/sys/auth/login HTTP/11" 200 None
ERROR    self_developed_model.conftest:conftest.py:129 第4次登录失败: 登录失败: MFA验证失败
INFO     self_developed_model.conftest:conftest.py:100 UAT登录尝试 5/5，MFA验证码: 248708
DEBUG    urllib3.connectionpool:connectionpool.py:546 https://uat.atcp.top:443 "POST /api/sys/auth/login HTTP/11" 200 None
ERROR    self_developed_model.conftest:conftest.py:129 第5次登录失败: 登录失败: MFA验证失败
INFO     self_developed_model.conftest:conftest.py:62 [2025-10-09 14:22:18] 用例 test_vps/test_delete.py::TestDeleteUser::test_deleteTemplate 开始登录，环境: uat
INFO     self_developed_model.conftest:conftest.py:100 UAT登录尝试 1/5，MFA验证码: 248708
DEBUG    urllib3.connectionpool:connectionpool.py:1051 Starting new HTTPS connection (1): uat.atcp.top:443
DEBUG    urllib3.connectionpool:connectionpool.py:546 https://uat.atcp.top:443 "POST /api/sys/auth/login HTTP/11" 200 None
ERROR    self_developed_model.conftest:conftest.py:129 第1次登录失败: 登录失败: MFA验证失败
INFO     self_developed_model.conftest:conftest.py:100 UAT登录尝试 2/5，MFA验证码: 167615
DEBUG    urllib3.connectionpool:connectionpool.py:546 https://uat.atcp.top:443 "POST /api/sys/auth/login HTTP/11" 200 None
ERROR    self_developed_model.conftest:conftest.py:129 第2次登录失败: 登录失败: MFA验证失败
INFO     self_developed_model.conftest:conftest.py:100 UAT登录尝试 3/5，MFA验证码: 167615
DEBUG    urllib3.connectionpool:connectionpool.py:546 https://uat.atcp.top:443 "POST /api/sys/auth/login HTTP/11" 200 None
ERROR    self_developed_model.conftest:conftest.py:129 第3次登录失败: 登录失败: MFA验证失败
INFO     self_developed_model.conftest:conftest.py:100 UAT登录尝试 4/5，MFA验证码: 167615
DEBUG    urllib3.connectionpool:connectionpool.py:546 https://uat.atcp.top:443 "POST /api/sys/auth/login HTTP/11" 200 None
ERROR    self_developed_model.conftest:conftest.py:129 第4次登录失败: 登录失败: MFA验证失败
INFO     self_developed_model.conftest:conftest.py:100 UAT登录尝试 5/5，MFA验证码: 918599
DEBUG    urllib3.connectionpool:connectionpool.py:546 https://uat.atcp.top:443 "POST /api/sys/auth/login HTTP/11" 200 None
ERROR    self_developed_model.conftest:conftest.py:129 第5次登录失败: 登录失败: MFA验证失败
INFO     self_developed_model.conftest:conftest.py:62 [2025-10-09 14:23:08] 用例 test_vps/test_delete.py::TestDeleteUser::test_deleteTemplate 开始登录，环境: uat
INFO     self_developed_model.conftest:conftest.py:100 UAT登录尝试 1/5，MFA验证码: 918599
DEBUG    urllib3.connectionpool:connectionpool.py:1051 Starting new HTTPS connection (1): uat.atcp.top:443
DEBUG    urllib3.connectionpool:connectionpool.py:546 https://uat.atcp.top:443 "POST /api/sys/auth/login HTTP/11" 200 None
ERROR    self_developed_model.conftest:conftest.py:129 第1次登录失败: 登录失败: MFA验证失败
INFO     self_developed_model.conftest:conftest.py:100 UAT登录尝试 2/5，MFA验证码: 918599
DEBUG    urllib3.connectionpool:connectionpool.py:546 https://uat.atcp.top:443 "POST /api/sys/auth/login HTTP/11" 200 None
ERROR    self_developed_model.conftest:conftest.py:129 第2次登录失败: 登录失败: MFA验证失败
INFO     self_developed_model.conftest:conftest.py:100 UAT登录尝试 3/5，MFA验证码: 918599
DEBUG    urllib3.connectionpool:connectionpool.py:546 https://uat.atcp.top:443 "POST /api/sys/auth/login HTTP/11" 200 None
INFO     self_developed_model.conftest:conftest.py:124 UAT登录成功（第3次尝试）
INFO     self_developed_model.commons.variable_manager:variable_manager.py:111 [2025-10-09 14:20] 运行时变量已保存到: D:\pycharm_test\self_developed_model\VAR\runtime_vars_vps.json
DEBUG    urllib3.connectionpool:connectionpool.py:546 https://uat.atcp.top:443 "DELETE /api/mascontrol/variety/deleteTemplate HTTP/11" 200 None
INFO     self_developed_model.commons.api_base:api_base.py:239 [2025-10-09 14:23:30] DELETE请求: /mascontrol/variety/deleteTemplate | 数据: [31]
INFO     self_developed_model.conftest:conftest.py:157 [2025-10-09 14:23:31] 用例 test_vps/test_delete.py::TestDeleteUser::test_deleteTemplate 执行完毕