INFO     self_developed_model.conftest:conftest.py:62 [2025-10-09 14:03:35] 用例 test_cloudTrader/test_delete.py::TestDelete_cloudTrader::test_delete_cloudTrader 开始登录，环境: uat
INFO     self_developed_model.conftest:conftest.py:100 UAT登录尝试 1/5，MFA验证码: 670979
DEBUG    urllib3.connectionpool:connectionpool.py:1051 Starting new HTTPS connection (1): uat.atcp.top:443
DEBUG    urllib3.connectionpool:connectionpool.py:546 https://uat.atcp.top:443 "POST /api/sys/auth/login HTTP/11" 200 None
ERROR    self_developed_model.conftest:conftest.py:129 第1次登录失败: 登录失败: MFA验证失败
INFO     self_developed_model.conftest:conftest.py:100 UAT登录尝试 2/5，MFA验证码: 670979
DEBUG    urllib3.connectionpool:connectionpool.py:546 https://uat.atcp.top:443 "POST /api/sys/auth/login HTTP/11" 200 None
ERROR    self_developed_model.conftest:conftest.py:129 第2次登录失败: 登录失败: MFA验证失败
INFO     self_developed_model.conftest:conftest.py:100 UAT登录尝试 3/5，MFA验证码: 670979
DEBUG    urllib3.connectionpool:connectionpool.py:546 https://uat.atcp.top:443 "POST /api/sys/auth/login HTTP/11" 200 None
INFO     self_developed_model.conftest:conftest.py:124 UAT登录成功（第3次尝试）
INFO     self_developed_model.commons.variable_manager:variable_manager.py:111 [2025-10-09 14:03] 运行时变量已保存到: D:\pycharm_test\self_developed_model\VAR\runtime_vars_cloud.json
DEBUG    urllib3.connectionpool:connectionpool.py:546 https://uat.atcp.top:443 "DELETE /api/mascontrol/cloudTrader HTTP/11" 200 None
INFO     self_developed_model.commons.api_base:api_base.py:239 [2025-10-09 14:03:57] DELETE请求: /mascontrol/cloudTrader | 数据: {'idList': [3265], 'isForceDel': 1}
INFO     self_developed_model.conftest:conftest.py:157 [2025-10-09 14:03:58] 用例 test_cloudTrader/test_delete.py::TestDelete_cloudTrader::test_delete_cloudTrader 执行完毕