{"uuid": "34cdb26d-78ff-419f-9260-4bf6b5ac2029", "children": ["658a4472-3e18-4b03-9e31-5368fe885bf1"], "befores": [{"name": "logged_session", "status": "failed", "statusDetails": {"message": "Failed: UAT登录失败（已重试5次）: 登录失败: MFA验证失败\n", "trace": "  File \"D:\\pycharm_test\\Community\\lib\\site-packages\\pluggy\\_callers.py\", line 167, in _multicall\n    teardown.throw(outcome._exception)\n  File \"D:\\pycharm_test\\Community\\lib\\site-packages\\_pytest\\setuponly.py\", line 36, in pytest_fixture_setup\n    return (yield)\n  File \"D:\\pycharm_test\\Community\\lib\\site-packages\\pluggy\\_callers.py\", line 103, in _multicall\n    res = hook_impl.function(*args)\n  File \"D:\\pycharm_test\\Community\\lib\\site-packages\\_pytest\\fixtures.py\", line 1140, in pytest_fixture_setup\n    result = call_fixture_func(fixturefunc, request, kwargs)\n  File \"D:\\pycharm_test\\Community\\lib\\site-packages\\_pytest\\fixtures.py\", line 891, in call_fixture_func\n    fixture_result = next(generator)\n  File \"D:\\pycharm_test\\self_developed_model\\conftest.py\", line 131, in logged_session\n    pytest.fail(f\"UAT登录失败（已重试{max_retries}次）: {str(e)}\", pytrace=False)\n  File \"D:\\pycharm_test\\Community\\lib\\site-packages\\_pytest\\outcomes.py\", line 178, in fail\n    raise Failed(msg=reason, pytrace=pytrace)\n"}, "start": 1759990890332, "stop": 1759990933827}], "start": 1759990890332, "stop": 1759990933836}