DEBUG    urllib3.connectionpool:connectionpool.py:546 https://dev.lgcopytrade.top:443 "POST /api/blockchain/account/bind HTTP/11" 200 None
INFO     template.commons.api_base:api_base.py:192 [2025-09-25 16:44:13] POST请求（JSON+URL参数）: /blockchain/account/bind | URL参数: None | JSON数据: {'userId': '1962808746181640193', 'brokerId': '1781213961048682529', 'serverId': '1821740479986667521', 'account': '301392106', 'password': '0sgsgtu', 'display': 'PRIVATE', 'passwordType': '0', 'subscribeFee': '0', 'type': 'SLAVE_REAL', 'platform': '4'}
INFO     template.commons.api_base:api_base.py:213 [2025-09-25 16:44:13] 请求后等待 3 秒
ERROR    template.commons.api_base:api_base.py:559 [2025-09-25 16:44:16] JSON断言失败: Failed: 账号301392106绑定失败（JSON路径值不匹配） | 路径: $.success | 响应: {"success":false,"message":"ConnectException: Connection refused (Connection refused)","code":500,"result":null,"timestamp":1758789853435}
ERROR    root:test_add_create.py:431 账号301392106执行失败：Failed: 账号301392106绑定失败（JSON断言失败）
Traceback (most recent call last):
  File "D:\pycharm_test\template\commons\api_base.py", line 552, in assert_json_value
    assert actual_value == expected_value, \
AssertionError: Failed: 账号301392106绑定失败（JSON路径值不匹配）

The above exception was the direct cause of the following exception:

Traceback (most recent call last):
  File "D:\pycharm_test\template\test_cloudTrader\test_add_create.py", line 216, in test_follow_full_flow
    self.assert_json_value(
  File "D:\pycharm_test\template\commons\api_base.py", line 561, in assert_json_value
    raise AssertionError(f"Failed: {error_msg_prefix}（JSON断言失败）") from e
AssertionError: Failed: 账号301392106绑定失败（JSON断言失败）