INFO     template.conftest:conftest.py:72 [2025-09-16 09:15:44] 用例  开始登录，环境: uat
ERROR    template.conftest:conftest.py:189 第1次登录失败: HTTPSConnectionPool(host='dev.lgcopytrade.top', port=443): Max retries exceeded with url: /api/sys/randomImage/1757985344305?_t=1757985344 (Caused by ProxyError('Unable to connect to proxy', FileNotFoundError(2, 'No such file or directory')))
ERROR    template.conftest:conftest.py:189 第2次登录失败: HTTPSConnectionPool(host='dev.lgcopytrade.top', port=443): Max retries exceeded with url: /api/sys/randomImage/1757985354337?_t=1757985354 (Caused by ProxyError('Unable to connect to proxy', FileNotFoundError(2, 'No such file or directory')))
ERROR    template.conftest:conftest.py:189 第3次登录失败: HTTPSConnectionPool(host='dev.lgcopytrade.top', port=443): Max retries exceeded with url: /api/sys/randomImage/1757985364365?_t=1757985364 (Caused by ProxyError('Unable to connect to proxy', FileNotFoundError(2, 'No such file or directory')))
ERROR    template.conftest:conftest.py:189 第4次登录失败: HTTPSConnectionPool(host='dev.lgcopytrade.top', port=443): Max retries exceeded with url: /api/sys/randomImage/1757985374389?_t=1757985374 (Caused by ProxyError('Unable to connect to proxy', FileNotFoundError(2, 'No such file or directory')))
ERROR    template.conftest:conftest.py:189 第5次登录失败: HTTPSConnectionPool(host='dev.lgcopytrade.top', port=443): Max retries exceeded with url: /api/sys/randomImage/1757985384409?_t=1757985384 (Caused by ProxyError('Unable to connect to proxy', FileNotFoundError(2, 'No such file or directory')))