{
  "uid" : "bfdd0302f9abdc9c",
  "name" : "账号管理-交易员账号-绑定交易员-用户列表-提取用户id",
  "fullName" : "test_community.test_lianxi.Test_proportionall#test_user_list",
  "historyId" : "b25ef44080beb4a56ec199f1c34a6f87",
  "time" : {
    "start" : 1760578096806,
    "stop" : 1760578096806,
    "duration" : 0
  },
  "status" : "failed",
  "statusMessage" : "Failed: dev环境登录失败（已重试5次）: HTTPSConnectionPool(host='dev.lgcopytrade.top', port=443): Max retries exceeded with url: /api/sys/randomImage/1760578136901?_t=1760578136 (Caused by ProxyError('Unable to connect to proxy', FileNotFoundError(2, 'No such file or directory')))",
  "statusTrace" : "[Errno 2] No such file or directory\n\nThe above exception was the direct cause of the following exception:\nTraceback (most recent call last):\n  File \"D:\\pycharm_test\\Community\\lib\\site-packages\\urllib3\\connectionpool.py\", line 775, in urlopen\n    self._prepare_proxy(conn)\n  File \"D:\\pycharm_test\\Community\\lib\\site-packages\\urllib3\\connectionpool.py\", line 1044, in _prepare_proxy\n    conn.connect()\n  File \"D:\\pycharm_test\\Community\\lib\\site-packages\\urllib3\\connection.py\", line 702, in connect\n    self.sock = sock = self._connect_tls_proxy(self.host, sock)\n  File \"D:\\pycharm_test\\Community\\lib\\site-packages\\urllib3\\connection.py\", line 802, in _connect_tls_proxy\n    sock_and_verified = _ssl_wrap_socket_and_match_hostname(\n  File \"D:\\pycharm_test\\Community\\lib\\site-packages\\urllib3\\connection.py\", line 909, in _ssl_wrap_socket_and_match_hostname\n    ssl_sock = ssl_wrap_socket(\n  File \"D:\\pycharm_test\\Community\\lib\\site-packages\\urllib3\\util\\ssl_.py\", line 469, in ssl_wrap_socket\n    ssl_sock = _ssl_wrap_socket_impl(sock, context, tls_in_tls, server_hostname)\n  File \"D:\\pycharm_test\\Community\\lib\\site-packages\\urllib3\\util\\ssl_.py\", line 513, in _ssl_wrap_socket_impl\n    return ssl_context.wrap_socket(sock, server_hostname=server_hostname)\n  File \"D:\\python_tools\\python\\lib\\ssl.py\", line 500, in wrap_socket\n    return self.sslsocket_class._create(\n  File \"D:\\python_tools\\python\\lib\\ssl.py\", line 1040, in _create\n    self.do_handshake()\n  File \"D:\\python_tools\\python\\lib\\ssl.py\", line 1309, in do_handshake\n    self._sslobj.do_handshake()\nFileNotFoundError: [Errno 2] No such file or directory\n\nThe above exception was the direct cause of the following exception:\n\nurllib3.exceptions.ProxyError: ('Unable to connect to proxy', FileNotFoundError(2, 'No such file or directory'))\n\nThe above exception was the direct cause of the following exception:\nHTTPSConnectionPool(host='dev.lgcopytrade.top', port=443): Max retries exceeded with url: /api/sys/randomImage/1760578136901?_t=1760578136 (Caused by ProxyError('Unable to connect to proxy', FileNotFoundError(2, 'No such file or directory')))\n\nDuring handling of the above exception, another exception occurred:\nHTTPSConnectionPool(host='dev.lgcopytrade.top', port=443): Max retries exceeded with url: /api/sys/randomImage/1760578136901?_t=1760578136 (Caused by ProxyError('Unable to connect to proxy', FileNotFoundError(2, 'No such file or directory')))\n\nDuring handling of the above exception, another exception occurred:\ndev环境登录失败（已重试5次）: HTTPSConnectionPool(host='dev.lgcopytrade.top', port=443): Max retries exceeded with url: /api/sys/randomImage/1760578136901?_t=1760578136 (Caused by ProxyError('Unable to connect to proxy', FileNotFoundError(2, 'No such file or directory')))",
  "flaky" : false,
  "newFailed" : false,
  "beforeStages" : [ {
    "name" : "var_manager",
    "time" : {
      "start" : 1760578096807,
      "stop" : 1760578096808,
      "duration" : 1
    },
    "status" : "passed",
    "steps" : [ ],
    "attachments" : [ ],
    "parameters" : [ ],
    "shouldDisplayMessage" : false,
    "attachmentsCount" : 0,
    "hasContent" : false,
    "stepsCount" : 0
  }, {
    "name" : "test_group",
    "time" : {
      "start" : 1760578096807,
      "stop" : 1760578096807,
      "duration" : 0
    },
    "status" : "passed",
    "steps" : [ ],
    "attachments" : [ ],
    "parameters" : [ ],
    "shouldDisplayMessage" : false,
    "attachmentsCount" : 0,
    "hasContent" : false,
    "stepsCount" : 0
  }, {
    "name" : "logged_session",
    "time" : {
      "start" : 1760578096808,
      "stop" : 1760578136916,
      "duration" : 40108
    },
    "status" : "failed",
    "statusMessage" : "Failed: dev环境登录失败（已重试5次）: HTTPSConnectionPool(host='dev.lgcopytrade.top', port=443): Max retries exceeded with url: /api/sys/randomImage/1760578136901?_t=1760578136 (Caused by ProxyError('Unable to connect to proxy', FileNotFoundError(2, 'No such file or directory')))\n",
    "statusTrace" : "  File \"D:\\pycharm_test\\Community\\lib\\site-packages\\pluggy\\_callers.py\", line 167, in _multicall\n    teardown.throw(outcome._exception)\n  File \"D:\\pycharm_test\\Community\\lib\\site-packages\\_pytest\\setuponly.py\", line 36, in pytest_fixture_setup\n    return (yield)\n  File \"D:\\pycharm_test\\Community\\lib\\site-packages\\pluggy\\_callers.py\", line 103, in _multicall\n    res = hook_impl.function(*args)\n  File \"D:\\pycharm_test\\Community\\lib\\site-packages\\_pytest\\fixtures.py\", line 1140, in pytest_fixture_setup\n    result = call_fixture_func(fixturefunc, request, kwargs)\n  File \"D:\\pycharm_test\\Community\\lib\\site-packages\\_pytest\\fixtures.py\", line 891, in call_fixture_func\n    fixture_result = next(generator)\n  File \"D:\\pycharm_test\\template_back\\conftest.py\", line 194, in logged_session\n    pytest.fail(f\"{environment.value}环境登录失败（已重试{max_retries}次）: {str(e)}\", pytrace=False)\n  File \"D:\\pycharm_test\\Community\\lib\\site-packages\\_pytest\\outcomes.py\", line 178, in fail\n    raise Failed(msg=reason, pytrace=pytrace)\n",
    "steps" : [ ],
    "attachments" : [ ],
    "parameters" : [ ],
    "shouldDisplayMessage" : true,
    "attachmentsCount" : 0,
    "hasContent" : true,
    "stepsCount" : 0
  }, {
    "name" : "environment",
    "time" : {
      "start" : 1760578096807,
      "stop" : 1760578096807,
      "duration" : 0
    },
    "status" : "passed",
    "steps" : [ ],
    "attachments" : [ ],
    "parameters" : [ ],
    "shouldDisplayMessage" : false,
    "attachmentsCount" : 0,
    "hasContent" : false,
    "stepsCount" : 0
  }, {
    "name" : "api_session",
    "time" : {
      "start" : 1760578096808,
      "stop" : 1760578096808,
      "duration" : 0
    },
    "status" : "passed",
    "steps" : [ ],
    "attachments" : [ ],
    "parameters" : [ ],
    "shouldDisplayMessage" : false,
    "attachmentsCount" : 0,
    "hasContent" : false,
    "stepsCount" : 0
  } ],
  "testStage" : {
    "status" : "failed",
    "statusMessage" : "Failed: dev环境登录失败（已重试5次）: HTTPSConnectionPool(host='dev.lgcopytrade.top', port=443): Max retries exceeded with url: /api/sys/randomImage/1760578136901?_t=1760578136 (Caused by ProxyError('Unable to connect to proxy', FileNotFoundError(2, 'No such file or directory')))",
    "statusTrace" : "[Errno 2] No such file or directory\n\nThe above exception was the direct cause of the following exception:\nTraceback (most recent call last):\n  File \"D:\\pycharm_test\\Community\\lib\\site-packages\\urllib3\\connectionpool.py\", line 775, in urlopen\n    self._prepare_proxy(conn)\n  File \"D:\\pycharm_test\\Community\\lib\\site-packages\\urllib3\\connectionpool.py\", line 1044, in _prepare_proxy\n    conn.connect()\n  File \"D:\\pycharm_test\\Community\\lib\\site-packages\\urllib3\\connection.py\", line 702, in connect\n    self.sock = sock = self._connect_tls_proxy(self.host, sock)\n  File \"D:\\pycharm_test\\Community\\lib\\site-packages\\urllib3\\connection.py\", line 802, in _connect_tls_proxy\n    sock_and_verified = _ssl_wrap_socket_and_match_hostname(\n  File \"D:\\pycharm_test\\Community\\lib\\site-packages\\urllib3\\connection.py\", line 909, in _ssl_wrap_socket_and_match_hostname\n    ssl_sock = ssl_wrap_socket(\n  File \"D:\\pycharm_test\\Community\\lib\\site-packages\\urllib3\\util\\ssl_.py\", line 469, in ssl_wrap_socket\n    ssl_sock = _ssl_wrap_socket_impl(sock, context, tls_in_tls, server_hostname)\n  File \"D:\\pycharm_test\\Community\\lib\\site-packages\\urllib3\\util\\ssl_.py\", line 513, in _ssl_wrap_socket_impl\n    return ssl_context.wrap_socket(sock, server_hostname=server_hostname)\n  File \"D:\\python_tools\\python\\lib\\ssl.py\", line 500, in wrap_socket\n    return self.sslsocket_class._create(\n  File \"D:\\python_tools\\python\\lib\\ssl.py\", line 1040, in _create\n    self.do_handshake()\n  File \"D:\\python_tools\\python\\lib\\ssl.py\", line 1309, in do_handshake\n    self._sslobj.do_handshake()\nFileNotFoundError: [Errno 2] No such file or directory\n\nThe above exception was the direct cause of the following exception:\n\nurllib3.exceptions.ProxyError: ('Unable to connect to proxy', FileNotFoundError(2, 'No such file or directory'))\n\nThe above exception was the direct cause of the following exception:\nHTTPSConnectionPool(host='dev.lgcopytrade.top', port=443): Max retries exceeded with url: /api/sys/randomImage/1760578136901?_t=1760578136 (Caused by ProxyError('Unable to connect to proxy', FileNotFoundError(2, 'No such file or directory')))\n\nDuring handling of the above exception, another exception occurred:\nHTTPSConnectionPool(host='dev.lgcopytrade.top', port=443): Max retries exceeded with url: /api/sys/randomImage/1760578136901?_t=1760578136 (Caused by ProxyError('Unable to connect to proxy', FileNotFoundError(2, 'No such file or directory')))\n\nDuring handling of the above exception, another exception occurred:\ndev环境登录失败（已重试5次）: HTTPSConnectionPool(host='dev.lgcopytrade.top', port=443): Max retries exceeded with url: /api/sys/randomImage/1760578136901?_t=1760578136 (Caused by ProxyError('Unable to connect to proxy', FileNotFoundError(2, 'No such file or directory')))",
    "steps" : [ ],
    "attachments" : [ {
      "uid" : "47fe35169e1006e4",
      "name" : "log",
      "source" : "47fe35169e1006e4.txt",
      "type" : "text/plain",
      "size" : 2719
    } ],
    "parameters" : [ ],
    "shouldDisplayMessage" : true,
    "attachmentsCount" : 1,
    "hasContent" : true,
    "stepsCount" : 0
  },
  "afterStages" : [ {
    "name" : "var_manager::0",
    "time" : {
      "start" : 1760578136932,
      "stop" : 1760578136933,
      "duration" : 1
    },
    "status" : "passed",
    "steps" : [ ],
    "attachments" : [ ],
    "parameters" : [ ],
    "shouldDisplayMessage" : false,
    "attachmentsCount" : 0,
    "hasContent" : false,
    "stepsCount" : 0
  }, {
    "name" : "api_session::0",
    "time" : {
      "start" : 1760578136932,
      "stop" : 1760578136932,
      "duration" : 0
    },
    "status" : "passed",
    "steps" : [ ],
    "attachments" : [ ],
    "parameters" : [ ],
    "shouldDisplayMessage" : false,
    "attachmentsCount" : 0,
    "hasContent" : false,
    "stepsCount" : 0
  } ],
  "labels" : [ {
    "name" : "feature",
    "value" : "跟随方式-按比例"
  }, {
    "name" : "parentSuite",
    "value" : "test_community"
  }, {
    "name" : "suite",
    "value" : "test_lianxi"
  }, {
    "name" : "subSuite",
    "value" : "Test_proportionall"
  }, {
    "name" : "host",
    "value" : "DESKTOP-4S9CU1E"
  }, {
    "name" : "thread",
    "value" : "33456-MainThread"
  }, {
    "name" : "framework",
    "value" : "pytest"
  }, {
    "name" : "language",
    "value" : "cpython3"
  }, {
    "name" : "package",
    "value" : "test_community.test_lianxi"
  }, {
    "name" : "resultFormat",
    "value" : "allure2"
  } ],
  "parameters" : [ ],
  "links" : [ ],
  "hidden" : false,
  "retry" : false,
  "extra" : {
    "severity" : "normal",
    "retries" : [ ],
    "categories" : [ {
      "name" : "Product defects",
      "matchedStatuses" : [ ],
      "flaky" : false
    } ],
    "tags" : [ ]
  },
  "source" : "bfdd0302f9abdc9c.json",
  "parameterValues" : [ ]
}